Workbook

Sheet Summary
A1: Sprint 4 regression test
A2: Process: docs/REGRESSION_TESTING.md. Yellow cells are for you to fill in; everything else is pre-filled or calculated.
A4: Sprint | B4: 4
A5: Date tested
A6: Tested by
A7: Commit tested (main) | C7: git rev-parse --short HEAD
A8: Baseline | B8: a635cd6 (tag sprint-3, the end of Sprint 3, 18 Oct 2026)
A10: Automated checks | B10: Result | C10: Run by | D10: Notes
A11: CI is green on main for the commit tested | D11: GitHub Actions tab: lint, type-check, unit tests, test cases, build, migrations, end-to-end.
A12: npm run verify:permissions | D12: With npm run dev running in a second terminal.
A13: npm run verify:login | D13: With npm run dev running in a second terminal.
A16: Results | B16: Cases | C16: Pass | D16: Fail | E16: Changed by design | F16: Blocked | G16: Not run yet
A17: Kayalvizhi - Accounts, event requests, event information and equipment release | B17: =COUNT(Kayalvizhi!$A$5:$A$60) | C17: =COUNTIF(Kayalvizhi!$J$5:$J$60,"Pass") | D17: =COUNTIF(Kayalvizhi!$J$5:$J$60,"Fail") | E17: =COUNTIF(Kayalvizhi!$J$5:$J$60,"Changed by design") | F17: =COUNTIF(Kayalvizhi!$J$5:$J$60,"Blocked") | G17: =B17-SUM(C17:F17)
A18: Jordan - Review, planning, readiness, event outcomes and the waiting list | B18: =COUNT(Jordan!$A$5:$A$54) | C18: =COUNTIF(Jordan!$J$5:$J$54,"Pass") | D18: =COUNTIF(Jordan!$J$5:$J$54,"Fail") | E18: =COUNTIF(Jordan!$J$5:$J$54,"Changed by design") | F18: =COUNTIF(Jordan!$J$5:$J$54,"Blocked") | G18: =B18-SUM(C18:F18)
A19: Janelle - Venue catalogue, availability, notifications, registration and alternative equipment | B19: =COUNT(Janelle!$A$5:$A$56) | C19: =COUNTIF(Janelle!$J$5:$J$56,"Pass") | D19: =COUNTIF(Janelle!$J$5:$J$56,"Fail") | E19: =COUNTIF(Janelle!$J$5:$J$56,"Changed by design") | F19: =COUNTIF(Janelle!$J$5:$J$56,"Blocked") | G19: =B19-SUM(C19:F19)
A20: Sammi - Venue booking requests, registration setup and attendee lists | B20: =COUNT(Sammi!$A$5:$A$56) | C20: =COUNTIF(Sammi!$J$5:$J$56,"Pass") | D20: =COUNTIF(Sammi!$J$5:$J$56,"Fail") | E20: =COUNTIF(Sammi!$J$5:$J$56,"Changed by design") | F20: =COUNTIF(Sammi!$J$5:$J$56,"Blocked") | G20: =B20-SUM(C20:F20)
A21: Kristen - Equipment, the safety check and change requests | B21: =COUNT(Kristen!$A$5:$A$56) | C21: =COUNTIF(Kristen!$J$5:$J$56,"Pass") | D21: =COUNTIF(Kristen!$J$5:$J$56,"Fail") | E21: =COUNTIF(Kristen!$J$5:$J$56,"Changed by design") | F21: =COUNTIF(Kristen!$J$5:$J$56,"Blocked") | G21: =B21-SUM(C21:F21)
A22: Smoke run | B22: =COUNTA('Smoke run'!$A$5:$A$41) | C22: =COUNTIF('Smoke run'!$G$5:$G$41,"Pass") | D22: =COUNTIF('Smoke run'!$G$5:$G$41,"Fail") | G22: =B22-SUM(C22:D22)
A23: Total | B23: =SUM(B17:B22) | C23: =SUM(C17:C22) | D23: =SUM(D17:D22) | E23: =SUM(E17:E22) | F23: =SUM(F17:F22) | G23: =SUM(G17:G22)
A25: Result | B25: Meaning | E25: What to do
A26: Pass | B26: The app matches the expected result. | E26: Nothing.
A27: Fail | B27: The app is wrong. | E27: Raise a Jira bug linked to the story and put its key in Notes.
A28: Changed by design | B28: The app differs because a later story changed it on purpose. | E28: Name that story in Notes, and add the case to 'Out-of-date cases' if it is not there already.
A29: Blocked | B29: The case could not be run, e.g. its test data is missing. | E29: Say why in Notes.
A31: Rules
A32: Never run npx prisma db seed. Use the fixture script named in the blue row before each story.
A33: Do not type results into the story workbooks in docs/test-cases/. Everything for this run is in this file.
A34: If a fix merges after a Fail, rerun the case and add a new row for it under the original. Keep the Fail row.

Sheet Smoke run
A1: Sprint 4 regression: smoke run
A2: A relay on a call, before splitting up: each person stays logged in as their role(s) on their own laptop and does their steps when the event reaches them, in order. Take one new event, titled 'REG S4 Smoke', from request to cancellation, plus a second event for the withdrawal in step 36 - do not use any story's fixture events. Password for every account: password123. Use an event date about 4 weeks ahead, with times on the quarter hour (e.g. 10:00-12:00). Change 'Who' if you swap roles. Marking an event completed needs an event that has ended, so it is covered by SPM-36 on Jordan's sheet, not here.
A4: Step | B4: Who | C4: Role (log in as) | D4: What to do | E4: Check | F4: Stories | G4: Result | H4: Notes
A5: 1 | B5: Kristen | C5: Event Organiser rachel.ng@meridianfina.com | D5: Create an event request titled 'REG S4 Smoke', expected attendance 120. Save it as a draft, reopen it from My Events and submit it. | E5: Status is Submitted. My Events lists only Rachel's own events. | F5: SPM-23, 24, 25, 31
A6: 2 | B6: Kristen | C6: Event Coordinator Lead grace.lim@connectsphere.com | D6: Notifications: open 'New event request submitted'. Assignments: assign Daniel Tan to the event. | E6: The notification names the event. The top bar shows the role as Event Coordinator Lead. Status is Under review. Rachel sees Daniel Tan as the coordinator and has a notification naming him. | F6: SPM-30, 53, 84
A7: 3 | B7: Janelle | C7: Safety Officer hana.yusof@connectsphere.com | D7: All Events: look for the event. | E7: The event is not listed: this role sees events only from Approved onwards. | F7: SPM-94
A8: 4 | B8: Jordan | C8: Event Coordinator daniel.tan@connectsphere.com | D8: Notifications: confirm the assignment. Review Queue: open the event, click 'Review request', choose 'Ask the organiser for clarification', tick 'Purpose', write a message and click 'Send request'. | E8: A green 'Clarification requested' message shows. Status stays Under review, with an 'Open clarification' box. | F8: SPM-29, 53
A9: 5 | B9: Kristen | C9: Event Organiser | D9: Notifications: open 'Clarification requested'. On the event, click 'Update request', change the description and click 'Resubmit request'. | E9: The notification carries the coordinator's message. The event page reads 'Your updated request has been sent to Daniel Tan. It stays Under review.' | F9: SPM-26, 53
A10: 6 | B10: Jordan | C10: Event Coordinator | D10: Review the request again, approve it, then begin planning. | E10: Status is Planning. Rachel has a notification of the review outcome. | F10: SPM-28, 53, 54
A11: 7 | B11: Jordan | C11: Event Coordinator | D11: Update the event information with an ordinary edit (e.g. the description only). | E11: The change is saved. No arrangement is flagged and the status stays Planning. | F11: SPM-62
A12: 8 | B12: Jordan | C12: Event Coordinator | D12: Venue tab: request two venues for the same times: a main room (purpose "Main programme", 120 people) and a breakout room (purpose "Breakout", 40 people), each with its own layout. | E12: Both bookings show on the event as Pending, each with its own venue, purpose, times and hold expiry. Each venue was checked against its own attendance and layout. | F12: SPM-40, 41, 42, 44, 81, 82, 90, 93
A13: 9 | B13: Jordan | C13: Event Coordinator | D13: Equipment tab: record three requirements for three different items, each quantity 1. | E13: All three are saved and show as Requested. | F13: SPM-47
A14: 10 | B14: Kayalvizhi | C14: Technical Support Staff kenji.sato@connectsphere.com | D14: Equipment Requests: open the event's request and check availability. Reserve the first two lines. Mark the third 'Cannot be provided' with a note, click 'Suggest alternative', choose another item with stock, write a note and click 'Record suggestion'. Then mark one unrelated equipment item under maintenance and return it to available. | E14: Two lines show Reserved. The third shows Cannot be provided with the suggestion. 'Suggestion sent to the Coordinator.' appears. The item's status changes and changes back. | F14: SPM-48, 49, 50, 55, 77
A15: 11 | B15: Jordan | C15: Event Coordinator | D15: Equipment tab: on the third line click 'Accept', then 'Accept' in the dialog. | E15: 'Alternative accepted. Technical Support will reserve it.' appears. The line becomes the alternative item, status Requested. | F15: SPM-77
A16: 12 | B16: Kayalvizhi | C16: Technical Support Staff | D16: Open the event's request again and reserve the alternative. | E16: All three lines show Reserved. | F16: SPM-49, 77
... A41: 37 | B41: Everyone | C41: Every role | D41: Log in as each role in turn. | E41: Each role sees only its own sidebar links (organiser "My Events"; coordinator, Lead and Safety Officer "All Events"; only the coordinator has "Change Requests"), and the organiser sees only their own events. | F41: SPM-21, 22, 84

Sheet Kayalvizhi
A1: Kayalvizhi's cases: Accounts, event requests, event information and equipment release
A2: Run top to bottom. A blue row starts each story: run its fixture script first (never npx prisma db seed). READ FIRST at the top of Preconditions says what has changed since the case was written. IDs ending in -R were rewritten in the Sprint 3 run and are reused here. Fill in the yellow Result, Date tested and Notes cells.
A4: # | B4: Test case ID | C4: Title | D4: Linked AC | E4: Type | F4: Preconditions | G4: Test data | H4: Steps | I4: Expected results | J4: Result | K4: Date tested | L4: Notes / bug key
A5: SPM-21 User Login - no fixture script: uses the base seed data
A6: 1 | B6: SPM-21-TC01 | C6: Valid credentials sign the user in and open the dashboard | D6: AC1 | E6: Positive | F6: Demo data is seeded. No one is signed in. On the "Log in" page. | G6: Email: daniel.tan@connectsphere.com; Password: password123 | H6: 1. Enter "daniel.tan@connectsphere.com" into Email 2. Enter "password123" into Password 3. Click "Log in" | I6: The button shows "Logging in…" while the request is in flight. The browser moves to the Dashboard, headed "Welcome, Daniel Tan" with "Event Coordinator" beneath it, and the top bar shows the same role under the name. No error message is shown.
A7: 2 | B7: SPM-21-TC12 | C7: The signed-in user's role is named on the dashboard | D7: AC3 | E7: Positive | F7: Demo data is seeded. No one is signed in. | G7: Accounts: daniel.tan@connectsphere.com (Coordinator), marcus.wong@connectsphere.com (Venue Staff); Password: password123 | H7: 1. Log in as daniel.tan@connectsphere.com with password123 2. Read the subtitle under the welcome heading 3. Log out, then log in as marcus.wong@connectsphere.com with password123 4. Read the subtitle under the welcome heading again | I7: Daniel Tan's dashboard is headed "Welcome, Daniel Tan", subtitled "Event Coordinator" and the section heading reads "Awaiting your review". Marcus Wong's dashboard is headed "Welcome, Marcus Wong", subtitled "Venue Staff" and the section heading reads "Upcoming events".
A8: SPM-22 Role-Based Access – UI Verification - no fixture script: uses the base seed data
A9: 3 | B9: SPM-22-TC01 | C9: An Attendee's sidebar offers only the Attendee screens | D9: AC1 | E9: Positive | F9: Demo data is seeded. Logged in as Daniel Lim (daniel.lim@example.com / password123), an Attendee. | G9: Account: daniel.lim@example.com (Attendee) | H9: 1. Read every item in the left sidebar from top to bottom | I9: The sidebar reads exactly: Dashboard, Browse Events, My Registrations, Notifications. Review Queue, Venues, Equipment, Booking Requests and Assignments do not appear anywhere in the sidebar.
A10: 4 | B10: SPM-22-TC04 | C10: An Attendee opening an event sees only the Overview tab | D10: AC2 | E10: Positive | F10: Logged in as Daniel Lim (daniel.lim@example.com / password123), an Attendee. At least one confirmed event that is open for registration exists. | G10: Account: daniel.lim@example.com (Attendee) | H10: 1. Open the events list from the sidebar 2. Open the first event in the list 3. Read the row of tabs beneath the event title | I10: Only an Overview tab is shown. No Equipment, Venue, Discussion, Attendees, Readiness or History tab appears — not even greyed out.
A11: 5 | B11: SPM-22-TC17 | C11: Internal planning fields are absent from an Attendee's view of an event | D11: AC5 | E11: Positive | F11: Logged in as Daniel Lim (daniel.lim@example.com / password123), an Attendee. A confirmed event that is open for registration exists and has a coordinator assigned, an expected attendance and special requirements recorded. | G11: Account: daniel.lim@example.com (Attendee) | H11: 1. Open the events list from the sidebar 2. Open the first event in the list 3. Read every label and value shown on the page from top to bottom | I11: The page shows the event's title, description, category, dates and status, and what is needed to register. There is no Coordinator row, no Organiser row, no Expected attendance row, no Special requirements row, no Rejection reason row and no venue or equipment arrangements. Those labels are absent entirely — the page does not show them with an empty value or a dash.
A12: 6 | B12: SPM-22-TC19 | C12: The Operations Manager's navigation matches their permissions | D12: AC6 | E12: Positive | F12: READ FIRST: v2 (2026-10-20): The Event Operations Manager is now shown as the 'Event Coordinator Lead' (SPM-84 AC1, forum #129, Week 7 Change #5) - the same role, accounts, permissions and pages. Read 'Operations Manager', 'Event Operations Manager' or 'Ops Manager' in this case as 'Event Coordinator Lead'; on screen the role is shown under its new name, and refusals say 'Assigning coordinators is the Event Coordinator Lead's role.' Logged in as Grace Lim (grace.lim@connectsphere.com / password123), an Operations Manager. | G12: Account: grace.lim@connectsphere.com (Operations Manager) | H12: 1. Read every item in the left sidebar from top to bottom 2. Read the role shown beneath the name in the top bar | I12: The sidebar reads exactly: Dashboard, Assignments, All Events, Notifications. The top bar shows Grace Lim with 'Operations Manager' beneath the name. Review Queue, Venues, Equipment and Booking Requests do not appear, because assigning coordinators and overseeing events is what this role does.
A13: SPM-84 Event Coordinator Lead: Rename Role and View Assignments - run npm run fixtures:spm84 before its first case
A14: 7 | B14: SPM-84-TC01 | C14: The Event Operations Manager is shown as the Event Coordinator Lead, with the same account, sidebar and Assignments screen as before | D14: AC1 | E14: Positive | F14: npm run fixtures:spm84 has been run. Grace Lim's account (grace.lim@connectsphere.com) is the role previously called Event Operations Manager. Logged out. | G14: Account: grace.lim@connectsphere.com / password123 (unchanged) | H14: 1. Log in as grace.lim@connectsphere.com / password123 2. Click 'Assignments' in the sidebar 3. Click 'All Events' in the sidebar | I14: Step 1: Login succeeds with the existing password. The top bar shows 'Grace Lim' and the role 'Event Coordinator Lead' - not 'Operations Manager'. The sidebar shows Dashboard, Assignments, All Events, Venues and Notifications, as before. Step 2: The 'Assignments' page opens with three tabs: 'Awaiting assignment', 'Active events' and 'Coordinators'. 'Operations Manager' does not appear anywhere on the page. Step 3: The All Events list opens as before, with no 'Operations Manager' wording.
A15: 8 | B15: SPM-84-TC02 | C15: The Coordinators tab lists every Event Coordinator with their number of active events, including one with none and a deactivated one who still holds an event | D15: AC4, AC10, AC6 | E15: Positive | F15: npm run fixtures:spm84 has been run. It creates four coordinator accounts of SPM-84's own: - Aisha Karim: SPM84 Harbour Gala (Planning), SPM84 Orchard Forum (Under review), SPM84 Postponed Retreat (Postponed) - active; SPM84 Closed Showcase (Completed), SPM84 Called Off Expo (Cancelled), SPM84 Rejected Request (Rejected), SPM84 Withdrawn Request (Withdrawn) - not active - Benjamin Lau: SPM84 Riverside Launch (Confirmed) - Clara Tay: SPM84 Past Seminar (Completed) only - Dennis Ho: account deactivated, still assigned SPM84 Inherited Workshop (Planning) Logged in as the Event Coordinator Lead, Grace Lim (grace.lim@connectsphere.com / password123). | G15: Coordinators: Aisha Karim (3 active), Benjamin Lau (1), Clara Tay (0), Dennis Ho (1, account inactive) | H15: 1. Click 'Assignments' in the sidebar 2. Click the 'Coordinators' tab | I15: Step 2: A table lists every Event Coordinator by name, A to Z, with an 'Active events' column. Aisha Karim shows 3 (her Completed, Cancelled, Rejected and Withdrawn events are not counted). Benjamin Lau shows 1. Clara Tay is listed with 0. Dennis Ho shows 1 and is labelled 'Account inactive'. The base coordinators (e.g. Daniel Tan, Priya Raj) are listed too.
A16: 9 | B16: SPM-84-TC03 | C16: The Active events tab, filtered to one coordinator, shows only their active events with coordinator, status, client and date, and each opens its event | D16: AC5, AC6, AC7, AC8 | E16: Positive | F16: npm run fixtures:spm84 has been run (Aisha Karim has three active and four inactive SPM84 events, all for the client Meridian Financial Group). Logged in as the Event Coordinator Lead, Grace Lim (grace.lim@connectsphere.com / password123). | G16: Coordinator filter: Aisha Karim | H16: 1. Click 'Assignments' in the sidebar 2. Click the 'Active events' tab 3. In 'Coordinator', choose 'Aisha Karim' 4. Click 'SPM84 Harbour Gala' | I16: Step 2: A table of active events opens with the columns Event, Client, When, Status, Coordinator and 'Reassign to', and the filters 'Coordinator' (set to 'Any coordinator') and 'Status' (set to 'Any status'). Step 3: Exactly three rows remain: 'SPM84 Harbour Gala' (Planning, 9 Nov 2027), 'SPM84 Orchard Forum' (Under review, 11 Nov 2027) and 'SPM84 Postponed Retreat' (Postponed, 16 Nov 2027), each with Client 'Meridian Financial Group' and Coordinator 'Aisha Karim'. SPM84 Closed Showcase, SPM84 Called Off Expo, SPM84 Rejected Request and SPM84 Withdrawn Request are not listed. Step 4: The event's Overview opens with the title 'SPM84 Harbour Gala', the status 'Planning', Coordinator 'Aisha Karim' and Company 'Meridian Financial Group', and a 'Change coordinator' card.
A17: 10 | B17: SPM-84-TC09 | C17: Reassigning from the Active events list moves the event to the new coordinator and updates both coordinators' counts | D17: AC9, AC11, AC2 | E17: Positive | F17: Run npm run fixtures:spm84 before and after this case ('SPM84 Harbour Gala' is assigned to Aisha Karim, who has 3 active events; Benjamin Lau has 1). Logged in as the Event Coordinator Lead, Grace Lim (grace.lim@connectsphere.com / password123). | G17: Event: SPM84 Harbour Gala | From: Aisha Karim | To: Benjamin Lau | H17: 1. Click 'Assignments' in the sidebar 2. Click the 'Active events' tab 3. In 'Coordinator', choose 'Aisha Karim' 4. On the 'SPM84 Harbour Gala' row, choose 'Benjamin Lau' in 'Reassign to' 5. Click 'Reassign' 6. Click 'Reassign' in the dialog 7. Click the 'Coordinators' tab | I17: Step 5: A dialog 'Reassign this event?' appears, saying Aisha Karim will no longer be able to manage it and that both coordinators are notified. Step 6: The message '"SPM84 Harbour Gala" has been reassigned from Aisha Karim to Benjamin Lau.' appears, and 'SPM84 Harbour Gala' leaves the list filtered to Aisha Karim. Step 7: Aisha Karim's 'Active events' count is now 2 and Benjamin Lau's is 2.
A18: SPM-23 Create Event Request - no fixture script: uses the base seed data
A19: 11 | B19: SPM-23-TC01 | C19: Organiser can enter an event name and purpose | D19: AC1 | E19: Positive | F19: Logged in as rachel.ng@meridianfina.com / password123 (a seeded Event Organiser). Use your own initials in place of "KC" in every event name below so your drafts never clash with another tester's. On the "New event request" page. | G19: Event name: Nusantara Product Launch 2026 - KC; Purpose: Regional product launch and press event | H19: 1. Enter "Nusantara Product Launch 2026 - KC" into Event name 2. Enter "Regional product launch and press event" into Purpose 3. Click "Save draft" | I19: The browser returns to "My events". The new draft appears with the title "Nusantara Product Launch 2026 - KC". Reopening it shows Purpose still filled in as "Regional product launch and press event".
A20: 12 | B20: SPM-23-TC03 | C20: Organiser can enter and save an event description | D20: AC2 | E20: Positive | F20: Logged in as rachel.ng@meridianfina.com / password123 (a seeded Event Organiser). Use your own initials in place of "KC" in every event name below so your drafts never clash with another tester's, on the "New event request" page. | G20: Description: Press event with livestream and product demonstration area. | H20: 1. Enter "Nusantara Product Launch 2026 - KC" into Event name 2. Enter "Press event with livestream and product demonstration area." into Description 3. Click "Save draft" 4. From "My events", open the draft again | I20: The draft is saved. Reopening it shows the Description field still reading "Press event with livestream and product demonstration area."
A21: 13 | B21: SPM-23-TC04 | C21: Organiser can specify the proposed date and time | D21: AC3 | E21: Positive | F21: Logged in as rachel.ng@meridianfina.com / password123 (a seeded Event Organiser). Use your own initials in place of "KC" in every event name below so your drafts never clash with another tester's, on the "New event request" page, with Event name "Nusantara Product Launch 2026 - KC", Type of event "Exhibition", and Expected attendance 200 already filled in. | G21: Event name: Nusantara Product Launch 2026 - KC; Starts at: 5 Dec 2026, 9:00 AM; Ends at: 5 Dec 2026, 5:00 PM | H21: 1. Set Starts at to 5 Dec 2026, 9:00 AM 2. Set Ends at to 5 Dec 2026, 5:00 PM 3. Click "Submit request" 4. Open the "My events" page | I21: No message appears and the request is submitted. "My events" lists it under "Submitted" (not under Drafts) with status "Submitted" and When "5 Dec 2026, 09:00–17:00"
A22: 14 | B22: SPM-23-TC07 | C22: Organiser can specify expected attendance | D22: AC4 | E22: Positive | F22: Logged in as rachel.ng@meridianfina.com / password123 (a seeded Event Organiser). Use your own initials in place of "KC" in every event name below so your drafts never clash with another tester's, on the "New event request" page, with Event name, Type of event, Starts at and Ends at already filled in with valid values. | G22: Expected attendance: 250 | H22: 1. Enter 250 into Expected attendance 2. Click "Submit request" 3. Open the "My events" page | I22: No message appears and the request is submitted. "My events" lists it under "Submitted" with status "Submitted" and Attendance 250.
A23: 15 | B23: SPM-23-TC10 | C23: Organiser can specify venue and accessibility requirements | D23: AC5 | E23: Positive | F23: Logged in as rachel.ng@meridianfina.com / password123 (a seeded Event Organiser). Use your own initials in place of "KC" in every event name below so your drafts never clash with another tester's, on the "New event request" page, with Event name "Nusantara Product Launch 2026 - KC" filled in. | G23: Event name: Nusantara Product Launch 2026 - KC; Venue requirement: High-density WiFi; Accessibility need: Wheelchair spaces | H23: 1. Tick "High-density WiFi" under "The venue must have" 2. Tick "Wheelchair spaces" under "Accessibility needs" 3. Click "Save draft" 4. From "My events", open the draft you just saved (find it by its name) | I23: The browser returns to "My events" and the draft is listed. Reopening it shows both "High-density WiFi" (under "The venue must have") and "Wheelchair spaces" (under "Accessibility needs") still ticked.
A24: 16 | B24: SPM-23-TC18 | C24: A fully completed request can be submitted | D24: AC7 | E24: Positive | F24: Logged in as rachel.ng@meridianfina.com / password123 (a seeded Event Organiser). Use your own initials in place of "KC" in every event name below so your drafts never clash with another tester's, on the "New event request" page. | G24: Event name: Nusantara Product Launch 2026 - KC; Type: Exhibition; Starts at: 5 Dec 2026, 9:00 AM; Ends at: 5 Dec 2026, 5:00 PM; Expected attendance: 200 | H24: 1. Enter "Nusantara Product Launch 2026 - KC" into Event name 2. Select "Exhibition" as Type of event 3. Set Starts at to 5 Dec 2026, 9:00 AM and Ends at to 5 Dec 2026, 5:00 PM 4. Enter 200 into Expected attendance 5. Click "Submit request" 6. Open the "My events" page | I24: No message appears and the request is submitted. "My events" lists it under "Submitted" (not under Drafts) with status "Submitted", When "5 Dec 2026, 09:00–17:00" and Attendance 200.
A25: 17 | B25: SPM-23-TC27 | C25: A multi-session draft is identifiable as a draft and shows the span and largest attendance | D25: AC6, AC8 | E25: Positive | F25: Logged in as rachel.ng@meridianfina.com / password123 (a seeded Event Organiser). Use your own initials in place of "KC" in every event name below so your drafts never clash with another tester's, on the "New event request" page, with Event name "Nusantara Summit 2026 - KC" and Type of event "Conference" already filled in, "This event has multiple sessions" ticked, Session 1 = 5 Dec 2026 9:00 AM - 5:00 PM (300 attendees) and Session 2 = 6 Dec 2026 9:00 AM - 5:00 PM (80 attendees). | G25: Event name: Nusantara Summit 2026 - KC; Session 1: 300 attendees; Session 2: 80 attendees | H25: 1. Click "Save draft" 2. Look at the new draft's row in "My events" | I25: The event appears under "Drafts - not yet submitted" with a "Draft" status badge, visually distinct from submitted requests. Its When column shows "5 Dec 2026, 09:00 – 6 Dec 2026, 17:00" (first session start to last session end) and Attendance shows 300 (the largest single session, not 380).
A26: SPM-24 Save Draft Event Request - no fixture script: uses the base seed data
A27: 18 | B27: SPM-24-TC06 | C27: Organiser can leave and return to a saved draft | D27: AC3 | E27: Positive | F27: Seeded draft "Q1 Investor Update (rough idea)" owned by rachel.ng@meridianfina.com. Its saved description reads "Still checking dates with the exec team." | G27: Login: rachel.ng@meridianfina.com / password123 | H27: 1. Log in as rachel.ng@meridianfina.com / password123 2. Log out 3. Log back in as rachel.ng@meridianfina.com / password123 4. Open the "My events" page 5. Click the "Q1 Investor Update (rough idea)" row | I27: The "Edit draft" page opens with every previously saved value already filled in, including the Description field reading "Still checking dates with the exec team." The Draft badge is still shown.
A28: 19 | B28: SPM-24-TC09 | C28: Editing a draft's fields saves the changes | D28: AC4 | E28: Positive | F28: Draft "Annual Partner Appreciation Dinner" from TC01, owned by rachel.ng@meridianfina.com, has no other fields set yet. | G28: Event name: Annual Partner Appreciation Dinner - Updated; Type of event: Conference; Starts at: 10 Nov 2026, 9:00 AM; Ends at: 10 Nov 2026, 5:00 PM | H28: 1. Log in as rachel.ng@meridianfina.com / password123 2. Open the draft's "Edit draft" page 3. Change Event name to "Annual Partner Appreciation Dinner - Updated" 4. Set Type of event to "Conference" 5. Set Starts at to 10 Nov 2026, 9:00 AM and Ends at to 10 Nov 2026, 5:00 PM 6. Click "Save draft" | I28: The browser returns to "My events". Status remains "Draft". Reopening the draft shows all the updated values.
A29: 20 | B29: SPM-24-TC14 | C29: A complete draft can be submitted and leaves draft status | D29: AC1, AC5 | E29: Positive | F29: The draft from TC09 has Event name, Type, Starts at and Ends at set. Expected attendance is still missing. | G29: Expected attendance: 120 (everything else already saved from TC09) | H29: 1. Open the draft's "Edit draft" page 2. Enter 120 into Expected attendance 3. Click "Submit request" | I29: The browser moves to the event's own page. Its status badge now reads "Submitted" instead of "Draft", and it no longer appears under "Drafts — not yet submitted" on "My events".
A30: SPM-25 Submit Event Request - no fixture script: uses the base seed data
A31: 21 | B31: SPM-25-TC01 | C31: Submitting a complete event request succeeds and moves it to Submitted | D31: AC1, AC2 | E31: Positive | F31: Logged in as an Event Organiser (e.g. rachel.ng@meridianfina.com). No existing event named 'Quarterly Town Hall' for this organiser. | G31: Event name: Quarterly Town Hall Type: Meeting Starts at: today + 7 days, 10:00 Ends at: today + 7 days, 11:00 Expected attendance: 50 | H31: 1. From the sidebar, click 'My Events' 2. Click 'New event request' 3. Enter the event name 'Quarterly Town Hall' 4. Select 'Meeting' as the type of event 5. Enter a Starts at date/time 7 days from today, 10:00 6. Enter an Ends at date/time 7 days from today, 11:00 7. Enter '50' as the Expected attendance 8. Click 'Submit request' 9. From the sidebar, click 'My Events' again | I31: No validation errors appear; the form submits without returning to the New event request page. On 'My Events', the event does NOT appear under 'Drafts — not yet submitted'. The event appears under 'Submitted' with a 'Submitted' status badge, the correct date/time range, and attendance '50'.
A32: 22 | B32: SPM-25-TC05 | C32: A submitted request no longer opens as an editable draft | D32: AC3 | E32: Positive | F32: The event from SPM-25-TC01 ('Quarterly Town Hall') has status 'Submitted'. Logged in as the organiser who owns it. | G32: Event: Quarterly Town Hall (status: Submitted) | H32: 1. From 'My Events', confirm 'Quarterly Town Hall' is listed only under 'Submitted', not under 'Drafts — not yet submitted' 2. Use the browser's Back button to return to the 'Edit draft' page for this event that was open earlier in TC01's session (or navigate back to it via browser history) 3. Observe the page that loads | I32: 'Quarterly Town Hall' is absent from the 'Drafts — not yet submitted' section. The 'Edit draft' page shows an alert titled 'Could not open this draft' with the message 'This request has already been submitted, so it can no longer be edited here.' No form fields are shown, and a 'Back to My Events' button is offered instead.
A33: 23 | B33: SPM-25-TC06 | C33: Event Coordinator can see a submitted request in All Events | D33: AC4 | E33: Positive | F33: The event from SPM-25-TC01 ('Quarterly Town Hall') has status 'Submitted'. Log out of the organiser account. | G33: Coordinator: daniel.tan@connectsphere.com Filter: Submitted | H33: 1. Log in as the Event Coordinator (e.g. daniel.tan@connectsphere.com) 2. From the sidebar, click 'All Events' 3. Use the 'Filter by status' dropdown to select 'Submitted' 4. Locate the 'Quarterly Town Hall' row | I33: 'Quarterly Town Hall' appears in the table with its date/time range, attendance '50', and a 'Submitted' status badge — confirming the coordinator can see the submitted request. Every other row in the table also shows a 'Submitted' status badge — the filter actually narrows the table to that status, rather than continuing to show every event regardless of the selected filter.
A34: SPM-26 Respond to Clarification Request - run npm run fixtures:spm26 before its first case
A35: 24 | B35: SPM-26-TC01 | C35: The organiser who raised the request sees the open clarification on the event and on the Update request page, with the request's current details filled in | D35: AC1, AC2 | E35: Positive | F35: Test data loaded: `npm run fixtures:spm26` has been run from the project folder (it only touches the 'SPM26 …' events, never anyone else's data). 'SPM26 Meridian Advisory Briefing' is Under review, raised by Rachel Ng and assigned to Daniel Tan, with a clarification Daniel Tan opened on 20 Oct 2026, 10:00 about Description and Expected attendance. Logged in as Event Organiser Rachel Ng (rachel.ng@meridianfina.com / password123). | G35: Event: SPM26 Meridian Advisory Briefing Clarification: Description, Expected attendance - 'How many advisers will attend, and is there a networking session after the briefing?' | H35: 1. Click 'My Events' in the sidebar and open 'SPM26 Meridian Advisory Briefing' 2. Click 'Update request' in the 'Clarification requested' banner 3. Click 'Cancel' | I35: Step 1: The event page shows the 'Under review' badge and an amber 'Clarification requested' banner listing 'Needs clarification: Description, Expected attendance', the message 'How many advisers will attend, and is there a networking session after the briefing?', 'Asked by Daniel Tan on 20 Oct 2026, 10:00' and an 'Update request' button. Step 2: The 'Update request' page opens with the 'Under review' badge. At the top a 'Clarification requested' box shows the same items, message and 'Asked by Daniel Tan on 20 Oct 2026, 10:00'. The form is filled in with the request as it stands: Event name 'SPM26 Meridian Advisory Briefing', Type of event 'Conference', Description 'Half-day session followed by networking.', Expected attendance '80', Preferred room layout 'Theatre'. At the bottom are 'Resubmit request' and 'Cancel'; there is no 'Save draft' or 'Submit request' button. Step 3: The event page opens again, still 'Under review', with the same 'Clarification requested' banner and Expected attendance '80'.
A36: 25 | B36: SPM-26-TC02 | C36: The organiser changes fields the coordinator asked about and one they did not, resubmits, and the event stays Under review with the clarification answered | D36: AC2, AC3, AC4 | E36: Positive | F36: THIS RUN: SPM-26-TC03 is not selected. Skip it, and run the fixture script once the selected cases that follow on from this one are done. Run `npm run fixtures:spm26` before this case: it resubmits 'SPM26 Meridian Advisory Briefing'. Go straight on to SPM-26-TC03 and reset after that one. 'SPM26 Meridian Advisory Briefing' is Under review, raised by Rachel Ng and assigned to Daniel Tan, with a clarification open about Description and Expected attendance. Logged in as Event Organiser Rachel Ng (rachel.ng@meridianfina.com / password123). | G36: Event: SPM26 Meridian Advisory Briefing Description: Half-day briefing for 120 advisers, followed by a networking lunch. Expected attendance: 120 (was 80) Preferred room layout: Classroom (was Theatre - not one of the items the coordinator asked about) | H36: 1. Click 'My Events' in the sidebar and open 'SPM26 Meridian Advisory Briefing' 2. Click 'Update request' in the 'Clarification requested' banner 3. Replace 'Description' with the new description 4. Replace 'Expected attendance' with 120 5. Change 'Preferred room layout' to 'Classroom' 6. Click 'Resubmit request' 7. Click 'My Events' in the sidebar | I36: Step 6: The event page opens with a green message 'Your updated request has been sent to Daniel Tan. It stays Under review.' The status badge reads 'Under review', no 'Clarification requested' banner is shown, and Details shows Expected attendance '120', Preferred layout 'Classroom' and Description 'Half-day briefing for 120 advisers, followed by a networking lunch.' Step 7: 'SPM26 Meridian Advisory Briefing' is listed with the 'Under review' badge.
A37: SPM-29 Request Event Clarification - run npm run fixtures:spm29 before its first case
A38: 26 | B38: SPM-29-TC02 | C38: The assigned coordinator sends a clarification request and the event stays Under review with the request shown on it | D38: AC1, AC2, AC3, AC4 | E38: Positive | F38: Run `npm run fixtures:spm29` before this case (and again after it): it sends a request on 'SPM29 Meridian Clarity Summit'. 'SPM29 Meridian Clarity Summit' is Under review, assigned to Daniel Tan, raised by Rachel Ng, with no clarification open. Logged in as Event Coordinator Daniel Tan (daniel.tan@connectsphere.com / password123). | G38: Event: SPM29 Meridian Clarity Summit Items: Purpose, When Message: Is this a dinner or a conference? Which day do you need? | H38: 1. Click 'Review Queue' in the sidebar and open 'SPM29 Meridian Clarity Summit' 2. Click 'Review request' 3. Choose 'Ask the organiser for clarification' 4. Tick 'Purpose' and 'When' under 'What needs clarification' 5. Type the message in 'Message to the organiser' 6. Click 'Send request' 7. Click 'Review Queue' in the sidebar 8. Open 'SPM29 Meridian Clarity Summit' 9. Log out and log in as Event Organiser Rachel Ng (rachel.ng@meridianfina.com / password123) 10. Click 'My Events' in the sidebar and open 'SPM29 Meridian Clarity Summit' | I38: Step 6: A green 'Clarification requested' message says the event stays Under review and the organiser can see the request on the event. The status badge at the top still reads 'Under review'. An 'Open clarification' box shows 'Purpose, When', the message 'Is this a dinner or a conference? Which day do you need?' and 'Asked by Daniel Tan' with today's date and time. 'Ask the organiser for clarification' is no longer offered, while 'Approve — planning can start' and 'Reject this request' still are. Step 7: 'SPM29 Meridian Clarity Summit' is still listed in the Review Queue with the 'Under review' badge. Step 8: The event page shows the 'Under review' badge and an amber 'Clarification requested' banner with 'Purpose, When', the message and 'Asked by Daniel Tan' with today's date and time. Step 10: Rachel Ng's event page shows the 'Under review' badge and the same 'Clarification requested' banner with 'Purpose, When', the message and 'Asked by Daniel Tan'.
A39: SPM-59 Record Request Withdrawal - run npm run fixtures:spm59 before its first case
A40: 27 | B40: SPM-59-TC01 | C40: The assigned coordinator records the organiser's withdrawal of a request under review, and its status changes to Withdrawn | D40: AC1, AC2 | E40: Positive | F40: THIS RUN: SPM-59-TC02 is not selected. Skip it, and run the fixture script once the selected cases that follow on from this one are done. Run npm run fixtures:spm59 before this case. 'SPM59 Harbour Strategy Day' is Under review, organised by Rachel Ng and assigned to Daniel Tan. Logged in as daniel.tan@connectsphere.com / password123 (Event Coordinator). SPM-59-TC02 continues from this case, so go straight to it and run npm run fixtures:spm59 after it. | G40: Event: SPM59 Harbour Strategy Day (Under review, coordinator Daniel Tan) | H40: 1. Click 'All Events' in the sidebar and open 'SPM59 Harbour Strategy Day' 2. Click 'Record withdrawal' 3. Click 'Keep request' in the dialog 4. Click 'Record withdrawal' again 5. Click 'Record withdrawal' in the dialog 6. Click 'Review Queue' in the sidebar | I40: Step 1: The event page shows the 'Under review' status badge, the 'This request is waiting for your review' alert and a 'Record withdrawal' button. Step 2: A dialog 'Record this withdrawal?' reads 'Only do this when the organiser has asked to withdraw. SPM59 Harbour Strategy Day will be marked Withdrawn and can't be reopened. To go ahead later, the organiser submits a new request.' with the buttons 'Keep request' and 'Record withdrawal'. Step 3: The dialog closes and the status badge still reads 'Under review'. Step 5: A green alert reads 'The withdrawal has been recorded.' The status badge reads 'Withdrawn', Status in the Details card reads 'Withdrawn', and the 'Record withdrawal' button and the 'This request is waiting for your review' alert are gone. Step 6: 'SPM59 Harbour Strategy Day' is not listed.
A41: 28 | B41: SPM-59-TC05 | C41: On My Events a withdrawn request has its own Withdrawn badge, distinct from Draft, Submitted, Approved and Rejected requests, and its own status filter | D41: AC3, AC5 | E41: Positive | F41: npm run fixtures:spm59 has been run. Rachel Ng organises 'SPM59 Draft Offsite' (Draft), 'SPM59 Submitted Briefing' (Submitted), 'SPM59 Approved Seminar' (Approved), 'SPM59 Rejected Gala' (Rejected) and 'SPM59 Withdrawn Product Launch' (Withdrawn). Logged in as rachel.ng@meridianfina.com / password123. Nothing is saved in this case. | G41: Organiser: Rachel Ng Events: SPM59 Draft Offsite, SPM59 Submitted Briefing, SPM59 Approved Seminar, SPM59 Rejected Gala, SPM59 Withdrawn Product Launch | H41: 1. Click 'My Events' in the sidebar 2. Choose 'Withdrawn' in 'Filter by status' | I41: Step 1: 'SPM59 Draft Offsite' is listed under 'Drafts — not yet submitted'. Under 'Submitted', 'SPM59 Submitted Briefing' shows 'Submitted', 'SPM59 Approved Seminar' 'Approved', 'SPM59 Rejected Gala' 'Rejected' and 'SPM59 Withdrawn Product Launch' 'Withdrawn' - each its own badge. Step 2: 'SPM59 Withdrawn Product Launch' is listed and every row shows 'Withdrawn'. None of the other four SPM59 events is listed.
...

Sheet Jordan
A1: Jordan's cases: Review, planning, readiness, event outcomes and the waiting list
A2: Run top to bottom. A blue row starts each story: run its fixture script first (never npx prisma db seed). READ FIRST at the top of Preconditions says what has changed since the case was written. IDs ending in -R were rewritten in the Sprint 3 run and are reused here. Fill in the yellow Result, Date tested and Notes cells.
A4: # | B4: Test case ID | C4: Title | D4: Linked AC | E4: Type | F4: Preconditions | G4: Test data | H4: Steps | I4: Expected results | J4: Result | K4: Date tested | L4: Notes / bug key
A5: SPM-28 Review Event Request - run npm run fixtures:spm28 before its first case
A6: 1 | B6: SPM-28-TC01 | C6: Review Queue lists only the Under review events assigned to the logged-in coordinator | D6: AC1 | E6: Positive | F6: Test data loaded: `npm run fixtures:spm28` has been run from the project folder since the last full `npx prisma db seed` (it only touches the 'SPM28 …' events, EVT-000124 to EVT-000130, never anyone else's data). Logged in as Daniel Tan (daniel.tan@connectsphere.com / password123), Event Coordinator. | G6: Must appear (Under review, coordinator Daniel Tan): SPM28 Nusantara Product Launch (EVT-000124), SPM28 Harbourline Client Seminar (EVT-000125) | Must not appear: SPM28 Kirana Regional Offsite (EVT-000126, coordinator Priya Raj), SPM28 Straits Journal Club (EVT-000127, coordinator Joel Fernandez) | H6: 1. Click 'Review Queue' in the sidebar | I6: Step 1: The Review Queue page lists 'SPM28 Nusantara Product Launch' (client 'Nusantara Tech Labs', 17 Mar 2027, 'Under review' badge) and 'SPM28 Harbourline Client Seminar'. Other Under review events assigned to Daniel Tan may also appear; only the SPM28 events are checked here. 'SPM28 Kirana Regional Offsite' and 'SPM28 Straits Journal Club' are not listed.
A7: 2 | B7: SPM-28-TC05 | C7: Review page displays all requirements of the request | D7: AC2 | E7: Positive | F7: Test data loaded: `npm run fixtures:spm28` has been run from the project folder since the last full `npx prisma db seed` (it only touches the 'SPM28 …' events, EVT-000124 to EVT-000130, never anyone else's data). Logged in as Daniel Tan (daniel.tan@connectsphere.com / password123), Event Coordinator. | G7: Event: SPM28 Nusantara Product Launch (EVT-000124) | Client: Nusantara Tech Labs | Organiser: Sari Widodo | Category: Exhibition | Purpose: Regional product launch and press event | Description: Press event with livestream and product demonstration area. | When: 17 Mar 2027, 15:00–19:00 | Expected attendance: 200 | Preferred layout: Theatre | Registration: Not enabled | Facilities: High-density WiFi (required), Raised stage (required), Livestream capability (required), Green room (nice-to-have) | Equipment: LED Video Wall Panel × 4, Streaming Encoder × 1 | Accessibility needs and Special requirements: left empty by the organiser | H7: 1. Click 'Review Queue' in the sidebar 2. Click 'SPM28 Nusantara Product Launch' | I7: Step 1: The Review Queue page opens and lists 'SPM28 Nusantara Product Launch'. Step 2: The 'Review request' page opens, with 'SPM28 Nusantara Product Launch' under the title and the 'Under review' badge. The 'What was requested' card shows every value in the test data next to its label, each facility followed by '(required)' or '(nice-to-have)', and each equipment item as 'name × quantity'. Accessibility needs and Special requirements show a 'Not provided' marker. No raw stored values (e.g. 'under_review', 'theatre') are shown.
A8: 3 | B8: SPM-28-TC06 | C8: Missing information is clearly flagged on the review page | D8: AC3 | E8: Positive | F8: Test data loaded: `npm run fixtures:spm28` has been run from the project folder since the last full `npx prisma db seed` (it only touches the 'SPM28 …' events, EVT-000124 to EVT-000130, never anyone else's data). Logged in as Joel Fernandez (joel.fernandez@connectsphere.com / password123), Event Coordinator assigned to 'SPM28 Straits Journal Club' (Under review). The request has no description, accessibility needs, special requirements, facilities or equipment. | G8: Event: SPM28 Straits Journal Club (EVT-000127) | Empty: Description, Accessibility needs, Special requirements, Facilities, Equipment | Filled: Purpose 'Monthly journal club', Expected attendance 30, Layout Boardroom | H8: 1. Click 'Review Queue' in the sidebar 2. Click 'SPM28 Straits Journal Club' | I8: Step 1: The Review Queue page opens and lists 'SPM28 Straits Journal Club'. Step 2: A yellow alert 'Some information was not provided' lists 'Description, Accessibility needs, Special requirements, Facilities, Equipment'. In 'What was requested', each of those rows shows a 'Not provided' marker (not blank or hidden). Purpose shows 'Monthly journal club', Expected attendance shows 30 and Preferred layout shows 'Boardroom'.
A9: 4 | B9: SPM-28-TC08 | C9: Coordinator approves a request for planning | D9: AC4, AC6 | E9: Positive | F9: Test data loaded: `npm run fixtures:spm28` has been run from the project folder since the last full `npx prisma db seed` (it only touches the 'SPM28 …' events, EVT-000124 to EVT-000130, never anyone else's data). Before: run `npm run fixtures:spm28` so 'SPM28 Harbourline Client Seminar' is back to Under review. Logged in as Daniel Tan (daniel.tan@connectsphere.com / password123), coordinator of 'SPM28 Harbourline Client Seminar' (Under review). After: run `npm run fixtures:spm28` so the next tester starts from the same state. It deletes and recreates only the 'SPM28 …' events - do NOT run `npx prisma db seed`, which wipes everyone's data. | G9: Event: SPM28 Harbourline Client Seminar (EVT-000125) | Outcome: Approve | H9: 1. Click 'Review Queue' in the sidebar 2. Click 'SPM28 Harbourline Client Seminar' 3. Select 'Approve — planning can start' 4. Click 'Approve request' 5. Click 'Approve' in the dialog 6. Click 'Review Queue' in the sidebar 7. Click 'All Events' in the sidebar and look for 'SPM28 Harbourline Client Seminar' | I9: Step 2: The 'Review request' page opens with the 'Under review' badge. Step 3: The option is highlighted and an 'Approve request' button is shown. Step 4: A dialog 'Approve this request?' appears, saying the event moves from Under review to Approved. The status has not changed yet. Step 5: A green 'Request approved' alert reads '"SPM28 Harbourline Client Seminar" is now Approved. Planning can start.' The status badge changes from 'Under review' to 'Approved' and the 'Your decision' card disappears. Step 6: 'SPM28 Harbourline Client Seminar' is no longer listed. Step 7: The event page shows the 'Approved' status badge, and no 'This request is waiting for your review' alert.
A10: 5 | B10: SPM-28-TC10 | C10: Coordinator rejects a request with a reason | D10: AC5, AC6 | E10: Positive | F10: Test data loaded: `npm run fixtures:spm28` has been run from the project folder since the last full `npx prisma db seed` (it only touches the 'SPM28 …' events, EVT-000124 to EVT-000130, never anyone else's data). Before: run `npm run fixtures:spm28` so 'SPM28 Kirana Regional Offsite' is back to Under review. Logged in as Priya Raj (priya.raj@connectsphere.com / password123), Event Coordinator assigned to 'SPM28 Kirana Regional Offsite' (Under review). | G10: Event: SPM28 Kirana Regional Offsite (EVT-000126) | Reason for rejection: Headcount was not confirmed after two reminders; please resubmit once numbers are final. | H10: 1. Click 'Review Queue' in the sidebar 2. Click 'SPM28 Kirana Regional Offsite' 3. Select 'Reject this request' 4. Type the reason into 'Reason for rejection' 5. Click 'Reject request' 6. Click 'Review Queue' in the sidebar | I10: Step 2: The 'Review request' page opens with the 'Under review' badge. Step 3: The 'Reason for rejection' field (marked required) and the 'Reject request' and 'Cancel' buttons appear. Step 5: A green 'Request rejected' alert reads '"SPM28 Kirana Regional Offsite" is now Rejected. The organiser can see your reason on the event.' followed by 'Reason:' and the reason exactly as typed. The status badge changes from 'Under review' to 'Rejected'. Step 6: 'SPM28 Kirana Regional Offsite' is no longer listed.
A11: SPM-30 Assign Event Coordinator - run npm run fixtures:spm30 before its first case
A12: 6 | B12: SPM-30-TC08 | C12: Ops Manager assigns a coordinator; it is recorded and the event moves to Under review | D12: AC1, AC2, AC3 | E12: Positive | F12: Test data loaded: run `npm run fixtures:spm30` from the project folder if it has not been run for this test pass. 'SPM30 Nusantara Developer Meetup' (organiser Budi Santoso, Nusantara Tech Labs) is Submitted with no coordinator. Logged in as Grace Lim (grace.lim@connectsphere.com / password123). Data reset: Changes data (assigns the event). TC09 and TC10 continue from this result, so reset only after TC10: run `npm run fixtures:spm30` from the project folder. | G12: Event: SPM30 Nusantara Developer Meetup | Coordinator: Daniel Tan | H12: 1. Click 'Assignments' in the sidebar 2. In the 'Assign to' dropdown for 'SPM30 Nusantara Developer Meetup', choose 'Daniel Tan' 3. Click 'Assign' 4. Click 'All Events' and open 'SPM30 Nusantara Developer Meetup' 5. Reload the page | I12: The message 'Daniel Tan is now the coordinator for "SPM30 Nusantara Developer Meetup". It has moved to Under review.' is shown. 'SPM30 Nusantara Developer Meetup' disappears from the 'Awaiting assignment' list. After reloading the event page, the status badge shows 'Under review' (previously 'Submitted') and the 'Details' card shows Coordinator 'Daniel Tan'.
A13: 7 | B13: SPM-30-TC10 | C13: Owning organiser sees the assigned coordinator | D13: AC5 | E13: Positive | F13: TC08 completed: Daniel Tan is assigned to 'SPM30 Nusantara Developer Meetup'. Logged in as Budi Santoso (budi.santoso@nusantaratec.com / password123), the event's organiser. Data reset: After this case, reset the data TC08 and TC09 changed: run `npm run fixtures:spm30` from the project folder. | G13: Event: SPM30 Nusantara Developer Meetup | Organiser: Budi Santoso | H13: 1. Click 'My Events' in the sidebar 2. Open 'SPM30 Nusantara Developer Meetup' | I13: The 'Details' card shows Coordinator 'Daniel Tan'.
A14: 8 | B14: SPM-30-TC13 | C14: Ops Manager reassigns an event from the event page | D14: AC6, AC3 | E14: Positive | F14: Test data loaded: run `npm run fixtures:spm30` from the project folder if it has not been run for this test pass. 'SPM30 Kirana Regional Offsite' (organiser Faridah Aziz) is Under review with coordinator Priya Raj. Logged in as Grace Lim (grace.lim@connectsphere.com / password123). Data reset: Changes data (reassigns the event). TC14 continues from this result, so reset only after TC14: run `npm run fixtures:spm30` from the project folder. | G14: Event: SPM30 Kirana Regional Offsite | From: Priya Raj | To: Joel Fernandez | H14: 1. Click 'All Events' 2. Open 'SPM30 Kirana Regional Offsite' 3. In the 'Change coordinator' card, choose 'Joel Fernandez' from the dropdown 4. Click 'Reassign' 5. Click 'Reassign' in the 'Reassign this event?' confirmation 6. Reload the page | I14: The confirmation says the event moves from Priya Raj to Joel Fernandez. The message 'Reassigned from Priya Raj to Joel Fernandez.' is shown. After reloading, the 'Details' card shows Coordinator 'Joel Fernandez'. The event status is unchanged (Under review).
A15: 9 | B15: SPM-30-TC14 | C15: After reassignment the previous coordinator loses access and the new one gains it | D15: AC6, AC4 | E15: Positive | F15: TC13 completed: 'SPM30 Kirana Regional Offsite' reassigned from Priya Raj to Joel Fernandez. Data reset: After this case, reset the data TC13 changed: run `npm run fixtures:spm30` from the project folder. | G15: Event: SPM30 Kirana Regional Offsite | Previous: Priya Raj | New: Joel Fernandez | H15: 1. Log in as Priya Raj (priya.raj@connectsphere.com / password123) 2. Open the Dashboard 3. Open 'SPM30 Kirana Regional Offsite' from 'All Events' and open the 'Equipment' tab 4. Log out and log in as Joel Fernandez (joel.fernandez@connectsphere.com / password123) 5. Open the Dashboard | I15: The event is no longer listed on Priya Raj's dashboard, and she sees no add/edit options on its Equipment tab. The event is listed under 'Awaiting your review' on Joel Fernandez's dashboard.
A16: SPM-54 Begin Event Planning - run npm run fixtures:spm54 before its first case
A17: 10 | B17: SPM-54-TC01 | C17: Pressing Search on Find a venue for an Approved event moves it to Planning | D17: AC1, AC2 | E17: Positive | F17: Test data loaded: `npm run fixtures:spm54` has been run from the project folder since the last full `npx prisma db seed` (it only touches the 'SPM54 …' events, EVT-000145 to EVT-000154, never anyone else's data). Before: run `npm run fixtures:spm54` so 'SPM54 Straits Clinical Forum' is back to Approved. Logged in as Daniel Tan (daniel.tan@connectsphere.com / password123), coordinator of 'SPM54 Straits Clinical Forum' (Approved). After: if you are running SPM-54-TC02 next, go straight to it - it needs this event in Planning. Otherwise run `npm run fixtures:spm54` so the next tester starts from the same state (never `npx prisma db seed`, which wipes everyone's data). | G17: Event: SPM54 Straits Clinical Forum (EVT-000145) | Starting status: Approved | Coordinator: Daniel Tan | Organiser: Evelyn Chen | H17: 1. Click 'All Events' in the sidebar and open 'SPM54 Straits Clinical Forum' 2. Click the 'Venue' tab 3. Click 'Search with filters' 4. Click 'Search' 5. Click 'Continue' in the dialog 6. Click 'EVT-000145' in the breadcrumb at the top of the page 7. Click 'All Events' in the sidebar | I17: Step 1: The event page shows EVT-000145 with the 'Approved' status badge, and 'Approved' next to Status in the Details card. Step 3: The 'Find a venue' search page opens with the subtitle 'Filled in from SPM54 Straits Clinical Forum's requirements. Change any filter and search again.' No 'Planning has started' alert is shown. Step 4: A dialog 'Begin planning?' reads 'This is the first venue or equipment action for this event, so it will move from Approved to Planning. The organiser and ConnectSphere staff will see this status. This cannot be undone.' with 'Cancel' and 'Continue' buttons. The status has not changed yet. Step 5: The dialog closes and the search runs. Above the filters, a green alert 'Planning has started' reads 'This event has moved from Approved to Planning now that its venue search has begun.' Step 6: The event page shows the 'Planning' status badge, and 'Planning' next to Status in the Details card. Step 7: The 'SPM54 Straits Clinical Forum' row shows 'Planning' in the Status column.
A18: 11 | B18: SPM-54-TC02 | C18: Organiser sees that their event has entered Planning | D18: AC4 | E18: Positive | F18: SPM-54-TC01 has just been run ('SPM54 Straits Clinical Forum' moved to Planning by Daniel Tan). Logged in as Evelyn Chen (evelyn.chen@straitsmedic.com / password123), Event Organiser of 'SPM54 Straits Clinical Forum'. After: run `npm run fixtures:spm54` so the next tester starts from the same state. It deletes and recreates only the 'SPM54 …' events - do NOT run `npx prisma db seed`, which wipes everyone's data. | G18: Event: SPM54 Straits Clinical Forum (EVT-000145) | Organiser: Evelyn Chen | Coordinator: Daniel Tan | H18: 1. Click 'Dashboard' in the sidebar 2. Click 'My Events' in the sidebar 3. Choose 'Planning' in 'Filter by status' 4. Click 'SPM54 Straits Clinical Forum' | I18: Step 1: Under the 'Planning' heading on the Dashboard, 'SPM54 Straits Clinical Forum' is listed with the 'Planning' status badge. It is the first event in that section (each section shows the five most recently updated) and is not under 'Approved'. Step 2: Under 'Submitted', 'SPM54 Straits Clinical Forum' is listed with 'Planning' in the Status column. Step 3: 'SPM54 Straits Clinical Forum' is still listed, and every listed event shows 'Planning'. Step 4: The event page shows EVT-000145 with the 'Planning' status badge. The Details card shows 'Planning' next to Status and 'Daniel Tan' next to Coordinator.
A19: 12 | B19: SPM-54-TC07 | C19: Removing an equipment item from an Approved event moves it to Planning | D19: AC1, AC3 | E19: Positive | F19: Test data loaded: `npm run fixtures:spm54` has been run from the project folder since the last full `npx prisma db seed` (it only touches the 'SPM54 …' events, EVT-000145 to EVT-000154, never anyone else's data). Before: run `npm run fixtures:spm54` so 'SPM54 Civic Trust Teachers Briefing' is back to Approved with its one equipment item. Logged in as Daniel Tan (daniel.tan@connectsphere.com / password123), coordinator of 'SPM54 Civic Trust Teachers Briefing' (Approved). Its organiser, Grace Abdullah, requested Handheld Wireless Mic × 1 when creating the event, so the item is already listed before planning begins. After: run `npm run fixtures:spm54` so the next tester starts from the same state. It deletes and recreates only the 'SPM54 …' events - do NOT run `npx prisma db seed`, which wipes everyone's data. | G19: Event: SPM54 Civic Trust Teachers Briefing (EVT-000154) | Starting status: Approved | Equipment removed: Handheld Wireless Mic (quantity 1) | H19: 1. Click 'All Events' in the sidebar and open 'SPM54 Civic Trust Teachers Briefing' 2. Click the 'Equipment' tab 3. Click 'Remove' on the 'Handheld Wireless Mic' row 4. Click 'Remove' in the dialog 5. Click the 'Overview' tab | I19: Step 1: The event page shows EVT-000154 with the 'Approved' status badge. Step 2: The 'Equipment requirements' page shows EVT-000154 with the 'Approved' status badge. The 'Requested items' card shows '1 item': 'Handheld Wireless Mic' with a 'Requested' badge and Quantity 1. Step 3: A dialog 'Remove this equipment requirement?' reads 'Technical Support will no longer see this item requested for this event.' followed by 'This is the first venue or equipment action for this event, so it will also move from Approved to Planning. The organiser and ConnectSphere staff will see this status. This cannot be undone.' The item is still listed and the status badge still shows 'Approved'. No separate 'Begin planning?' dialog appears. Step 4: The dialog closes and 'Nothing requested yet' is shown. A green alert 'Planning has started' reads 'This event has moved from Approved to Planning now that its equipment requirements are being worked on.', and the status badge at the top of the page changes to 'Planning'. Step 5: The event page shows the 'Planning' status badge, and 'Planning' next to Status in the Details card.
A20: SPM-33 Track Outstanding Arrangements - run npm run fixtures:spm33 before its first case
