Workbook

Sheet Summary
A1: Sprint 2 regression test
A2: Process: docs/REGRESSION_TESTING.md. Yellow cells are for you to fill in; everything else is pre-filled or calculated.
A4: Sprint | B4: 2
A5: Date tested
A6: Tested by
A7: Commit tested (main) | C7: git rev-parse --short HEAD
A8: Baseline | B8: 586bd68 (last commit on main before Sprint 2 started, 21 Sep 2026)
A10: Results | B10: Retested cases | C10: Smoke run | D10: Automated checks
A11: Total | B11: =COUNTA('Retested cases'!$A$5:$A$65) -> 61 | C11: =COUNTA('Smoke run'!$A$5:$A$12) -> 8 | D11: =COUNTA('Automated checks'!$A$5:$A$9) -> 5
A12: Pass | B12: =COUNTIF('Retested cases'!$I$5:$I$65,"Pass") -> 0 | C12: =COUNTIF('Smoke run'!$D$5:$D$12,"Pass") -> 0 | D12: =COUNTIF('Automated checks'!$C$5:$C$9,"Pass") -> 0
A13: Fail | B13: =COUNTIF('Retested cases'!$I$5:$I$65,"Fail") -> 0 | C13: =COUNTIF('Smoke run'!$D$5:$D$12,"Fail") -> 0 | D13: =COUNTIF('Automated checks'!$C$5:$C$9,"Fail") -> 0
A14: Changed by design | B14: =COUNTIF('Retested cases'!$I$5:$I$65,"Changed by design") -> 0
A15: Blocked | B15: =COUNTIF('Retested cases'!$I$5:$I$65,"Blocked") -> 0
A16: Not run yet | B16: =B11-SUM(B12:B15) -> 61 | C16: =C11-SUM(C12:C13) -> 8 | D16: =D11-SUM(D12:D13) -> 5
A19: Result | B19: Meaning | E19: What to do
A20: Pass | B20: The app matches the expected result. | E20: Nothing.
A21: Fail | B21: The app is wrong. | E21: Raise a Jira bug linked to the story. Add a row to Follow-ups.
A22: Changed by design | B22: The app differs because a later story changed the behaviour on purpose. | E22: Name that story in the notes. Add a row to Follow-ups so the test case gets updated.
A23: Blocked | B23: The case could not be run, for example because its test data no longer exists. | E23: Say why in the notes. Add a row to Follow-ups.
A26: Example of filled-in rows on 'Retested cases' (columns Result, Tested by, Date tested, Notes)
A27: SPM-47-TC01 | B27: Pass | C27: Janelle | D27: 2026-10-04
A28: SPM-40-TC15 | B28: Changed by design | C28: Kristen | D28: 2026-10-04 | E28: SPM-54 added the 'Begin planning?' step. Case needs updating.
A29: SPM-23-TC04 | B29: Fail | C29: Kristen | D29: 2026-10-04 | E29: Step 6: no confirmation message shown. Bug SPM-80.
A31: Rules
A32: Do not type results into the story workbooks in docs/test-cases/. They hold each story's original test run.
A33: Never run npx prisma db seed. Use the script in the Test data column, before the story and after any case that changes data.
A34: If a fix merges after a Fail, rerun the case and add a new row for it. Keep the Fail row.

Sheet Retested cases
A1: Sprint 2 regression: retested cases
A2: Read the steps in the story workbook (docs/test-cases/). Record the result here, not in the workbook. Fill in the yellow cells.
A4: Test case ID | B4: Story | C4: Title | D4: Linked AC | E4: Type | F4: Workbook | G4: Sheet | H4: Test data | I4: Result | J4: Tested by | K4: Date tested | L4: Notes / bug key
A5: SPM-21-TC01 | B5: SPM-21 | C5: Valid credentials sign the user in and open the dashboard | D5: AC1 | E5: Positive | F5: SPM-21_Test_Cases.xlsx | G5: TC01 | H5: Base seed data
A6: SPM-21-TC12 | B6: SPM-21 | C6: The signed-in user's role is named on the dashboard | D6: AC3 | E6: Positive | F6: SPM-21_Test_Cases.xlsx | G6: TC12 | H6: Base seed data
A7: SPM-22-TC01 | B7: SPM-22 | C7: An Attendee's sidebar offers only the Attendee screens | D7: AC1 | E7: Positive | F7: SPM-22_Test_Cases.xlsx | G7: TC01 | H7: Base seed data
A8: SPM-22-TC04 | B8: SPM-22 | C8: An Attendee opening an event sees only the Overview tab | D8: AC2 | E8: Positive | F8: SPM-22_Test_Cases.xlsx | G8: TC04 | H8: Base seed data
A9: SPM-22-TC17 | B9: SPM-22 | C9: Internal planning fields are absent from an Attendee's view of an event | D9: AC5 | E9: Positive | F9: SPM-22_Test_Cases.xlsx | G9: TC17 | H9: Base seed data
A10: SPM-22-TC19 | B10: SPM-22 | C10: The Operations Manager's navigation matches their permissions | D10: AC6 | E10: Positive | F10: SPM-22_Test_Cases.xlsx | G10: TC19 | H10: Base seed data
A11: SPM-23-TC01 | B11: SPM-23 | C11: Organiser can enter an event name and purpose | D11: AC1 | E11: Positive | F11: SPM-23_Test_Cases.xlsx | G11: TC01 | H11: Base seed data
A12: SPM-23-TC03 | B12: SPM-23 | C12: Organiser can enter and save an event description | D12: AC2 | E12: Positive | F12: SPM-23_Test_Cases.xlsx | G12: TC03 | H12: Base seed data
A13: SPM-23-TC04 | B13: SPM-23 | C13: Organiser can specify the proposed date and time | D13: AC3 | E13: Positive | F13: SPM-23_Test_Cases.xlsx | G13: TC04 | H13: Base seed data
A14: SPM-23-TC07 | B14: SPM-23 | C14: Organiser can specify expected attendance | D14: AC4 | E14: Positive | F14: SPM-23_Test_Cases.xlsx | G14: TC07 | H14: Base seed data
A15: SPM-23-TC10 | B15: SPM-23 | C15: Organiser can specify venue and accessibility requirements | D15: AC5 | E15: Positive | F15: SPM-23_Test_Cases.xlsx | G15: TC10 | H15: Base seed data
A16: SPM-23-TC18 | B16: SPM-23 | C16: A fully completed request can be submitted | D16: AC7 | E16: Positive | F16: SPM-23_Test_Cases.xlsx | G16: TC18 | H16: Base seed data
A17: SPM-23-TC27 | B17: SPM-23 | C17: A multi-session draft is identifiable as a draft and shows the span and largest attendance | D17: AC6, AC8 | E17: Positive | F17: SPM-23_Test_Cases.xlsx | G17: TC27 | H17: Base seed data
A18: SPM-24-TC01 | B18: SPM-24 | C18: Save Draft creates a saved draft with only a title | D18: AC1 | E18: Positive | F18: SPM-24_Test_Cases.xlsx | G18: TC01 | H18: Base seed data | L18: Run first: SPM-24-TC09 depends on it.
A19: SPM-24-TC06 | B19: SPM-24 | C19: Organiser can leave and return to a saved draft | D19: AC3 | E19: Positive | F19: SPM-24_Test_Cases.xlsx | G19: TC06 | H19: Base seed data
A20: SPM-24-TC09 | B20: SPM-24 | C20: Editing a draft's fields saves the changes | D20: AC4 | E20: Positive | F20: SPM-24_Test_Cases.xlsx | G20: TC09 | H20: Base seed data
A21: SPM-24-TC14 | B21: SPM-24 | C21: A complete draft can be submitted and leaves draft status | D21: AC1, AC5 | E21: Positive | F21: SPM-24_Test_Cases.xlsx | G21: TC14 | H21: Base seed data
A22: SPM-25-TC01 | B22: SPM-25 | C22: Submitting a complete event request succeeds and moves it to Submitted | D22: AC1, AC2 | E22: Positive | F22: SPM-25_Test_Cases.xlsx | G22: TC01 | H22: Base seed data
A23: SPM-25-TC05 | B23: SPM-25 | C23: A submitted request no longer opens as an editable draft | D23: AC3 | E23: Positive | F23: SPM-25_Test_Cases.xlsx | G23: TC05 | H23: Base seed data
A24: SPM-25-TC06 | B24: SPM-25 | C24: Event Coordinator can see a submitted request in All Events | D24: AC4 | E24: Positive | F24: SPM-25_Test_Cases.xlsx | G24: TC06 | H24: Base seed data
A25: SPM-28-TC01 | B25: SPM-28 | C25: Review Queue lists only the Under review events assigned to the logged-in coordinator | D25: AC1 | E25: Positive | F25: SPM-28_Test_Cases.xlsx | G25: TC01 | H25: npm run fixtures:spm28
A26: SPM-28-TC05 | B26: SPM-28 | C26: Review page displays all requirements of the request | D26: AC2 | E26: Positive | F26: SPM-28_Test_Cases.xlsx | G26: TC05 | H26: npm run fixtures:spm28
A27: SPM-28-TC06 | B27: SPM-28 | C27: Missing information is clearly flagged on the review page | D27: AC3 | E27: Positive | F27: SPM-28_Test_Cases.xlsx | G27: TC06 | H27: npm run fixtures:spm28
A28: SPM-28-TC08 | B28: SPM-28 | C28: Coordinator approves a request for planning | D28: AC4, AC6 | E28: Positive | F28: SPM-28_Test_Cases.xlsx | G28: TC08 | H28: npm run fixtures:spm28
A29: SPM-28-TC10 | B29: SPM-28 | C29: Coordinator rejects a request with a reason | D29: AC5, AC6 | E29: Positive | F29: SPM-28_Test_Cases.xlsx | G29: TC10 | H29: npm run fixtures:spm28
A30: SPM-30-TC08 | B30: SPM-30 | C30: Ops Manager assigns a coordinator; it is recorded and the event moves to Under review | D30: AC1, AC2, AC3 | E30: Positive | F30: SPM-30_Test_Cases.xlsx | G30: TC08 | H30: npm run fixtures:spm30
A31: SPM-30-TC10 | B31: SPM-30 | C31: Owning organiser sees the assigned coordinator | D31: AC5 | E31: Positive | F31: SPM-30_Test_Cases.xlsx | G31: TC10 | H31: npm run fixtures:spm30
A32: SPM-30-TC13 | B32: SPM-30 | C32: Ops Manager reassigns an event from the event page | D32: AC6, AC3 | E32: Positive | F32: SPM-30_Test_Cases.xlsx | G32: TC13 | H32: npm run fixtures:spm30 | L32: Run first: SPM-30-TC14 depends on it.
A33: SPM-30-TC14 | B33: SPM-30 | C33: After reassignment the previous coordinator loses access and the new one gains it | D33: AC6, AC4 | E33: Positive | F33: SPM-30_Test_Cases.xlsx | G33: TC14 | H33: npm run fixtures:spm30
A34: SPM-31-TC03 | B34: SPM-31 | C34: Opening a draft from 'My Events' goes straight to the draft editor, never the Overview tab | D34: AC1 | E34: Positive | F34: SPM-31_Test_Cases.xlsx | G34: TC03 | H34: Base seed data
A35: SPM-39-TC01 | B35: SPM-39 | C35: Venue Staff can create a venue record | D35: AC1 | E35: Positive | F35: SPM-39_Test_Cases.xlsx | G35: TC01 | H35: Base seed data
A36: SPM-39-TC05 | B36: SPM-39 | C36: Location, capacity, facilities and accessibility are all recorded and persist | D36: AC2 | E36: Positive | F36: SPM-39_Test_Cases.xlsx | G36: TC05 | H36: Base seed data
A37: SPM-39-TC07 | B37: SPM-39 | C37: Several layouts are recorded, each with its own capacity | D37: AC3 | E37: Positive | F37: SPM-39_Test_Cases.xlsx | G37: TC07 | H37: Base seed data
A38: SPM-39-TC10 | B38: SPM-39 | C38: Opening hours and turnaround times are recorded | D38: AC4 | E38: Positive | F38: SPM-39_Test_Cases.xlsx | G38: TC10 | H38: Base seed data
A39: SPM-39-TC13 | B39: SPM-39 | C39: Venue Staff can update an existing venue | D39: AC5 | E39: Positive | F39: SPM-39_Test_Cases.xlsx | G39: TC13 | H39: Base seed data
A40: SPM-39-TC15 | B40: SPM-39 | C40: A retired venue is no longer offered to a Coordinator | D40: AC6 | E40: Positive | F40: SPM-39_Test_Cases.xlsx | G40: TC15 | H40: Base seed data
A41: SPM-39-TC17 | B41: SPM-39 | C41: Reducing a layout below an approved booking's attendance flags that booking | D41: AC7 | E41: Positive | F41: SPM-39_Test_Cases.xlsx | G41: TC17 | H41: Base seed data
...

Sheet Automated checks
A1: Sprint 2 regression: automated checks
A2: Run on an up-to-date main. All five must pass before manual testing starts.
A4: Check | B4: Needs | C4: Result | D4: Run by | E4: Date run | F4: Notes
A5: npm test | B5: Nothing
A6: npm run lint | B6: Nothing
A7: npm run build | B7: Nothing
A8: npm run verify:permissions | B8: npm run dev in a second terminal
A9: npm run verify:login | B9: npm run dev in a second terminal

Sheet Scope
A1: Sprint 2 regression: scope
A2: Prepared 2026-10-02 against main at 8cd0ba8, plus the SPM-54 branch (in review). Recheck after the last merge of the sprint.
A4: Story | B4: Title | C4: Sprint | D4: Changes counted since | E4: In scope? | F4: Reason | G4: Cases selected
A5: SPM-21 | B5: User Login | C5: 1 | D5: End of Sprint 1 (586bd68) | E5: Yes | F5: Changed on main: src/app/dashboard/page.tsx, src/lib/apiAuth.ts Shared files changed: src/lib/permissions.ts, src/lib/roles.ts | G5: =COUNTIF('Retested cases'!$B$5:$B$65,A5) -> 2
A6: SPM-22 | B6: Role-Based Access - UI Verification | C6: 2 | D6: No merge commit found; test cases written 2026-09-26 (22a8f04) | E6: Yes | F6: Changed on main: src/app/assignments/page.tsx, src/app/events/[id]/page.tsx, src/app/queue/page.tsx, src/app/venues/page.tsx Shared files changed: src/lib/eventTabs.ts, src/lib/permissions.ts, src/lib/roles.ts | G6: =COUNTIF('Retested cases'!$B$5:$B$65,A6) -> 4
A7: SPM-23 | B7: Create Event Request | C7: 1 | D7: End of Sprint 1 (586bd68) | E7: Yes | F7: Changed on main: src/app/api/events/[id]/route.ts, src/app/api/events/route.ts, src/app/events/new/page.tsx, src/app/events/page.tsx, src/lib/validation/events.ts Shared files changed: prisma/schema.prisma, prisma/seed.ts | G7: =COUNTIF('Retested cases'!$B$5:$B$65,A7) -> 7
A8: SPM-24 | B8: Save Draft Event Request | C8: 1 | D8: End of Sprint 1 (586bd68) | E8: Yes | F8: Changed on main: src/app/api/events/[id]/route.ts, src/app/api/events/route.ts, src/app/events/new/page.tsx, src/app/events/page.tsx Shared files changed: prisma/seed.ts, src/lib/statuses.ts | G8: =COUNTIF('Retested cases'!$B$5:$B$65,A8) -> 4
A9: SPM-25 | B9: Submit Event Request | C9: 1 | D9: End of Sprint 1 (586bd68) | E9: Yes | F9: Changed on main: src/app/api/events/[id]/route.ts, src/app/events/new/page.tsx, src/app/events/page.tsx, src/lib/validation/events.ts Shared files changed: src/lib/permissions.ts, src/lib/roles.ts, src/lib/statuses.ts | G9: =COUNTIF('Retested cases'!$B$5:$B$65,A9) -> 3
A10: SPM-28 | B10: Review Event Request | C10: 2 | D10: Story merged 2026-10-01 (4859afd) | E10: Yes, once SPM-54 merges | F10: Changed by SPM-54 (not merged yet): src/app/api/events/[id]/route.ts Shared files changed: prisma/seed.ts, src/lib/permissions.ts, src/lib/statuses.ts | G10: =COUNTIF('Retested cases'!$B$5:$B$65,A10) -> 5
A11: SPM-30 | B11: Assign Event Coordinator | C11: 2 | D11: Story merged 2026-09-30 (1e4f40a) | E11: Yes | F11: Changed on main: src/app/api/events/[id]/route.ts, src/app/events/[id]/page.tsx Changed by SPM-54 (not merged yet): src/app/dashboard/page.tsx Shared files changed: prisma/seed.ts, src/lib/permissions.ts | G11: =COUNTIF('Retested cases'!$B$5:$B$65,A11) -> 4
A12: SPM-31 | B12: View Event Information | C12: 2 | D12: Story merged 2026-09-25 (424dfff) | E12: Yes | F12: Changed on main: src/app/api/events/[id]/equipment/route.ts, src/app/api/events/[id]/route.ts, src/app/dashboard/page.tsx, src/app/events/[id]/page.tsx, src/app/events/new/page.tsx Changed by SPM-54 (not merged yet): src/app/api/events/[id]/equipment/[requestId]/route.ts Shared files changed: prisma/schema.prisma, prisma/seed.ts, src/lib/eventTabs.ts, src/lib/format.ts, src/lib/permissions.ts, src/lib/roles.ts, src/lib/statuses.ts | G12: =COUNTIF('Retested cases'!$B$5:$B$65,A12) -> 1
A13: SPM-39 | B13: Manage Venue Catalogue | C13: 1 | D13: End of Sprint 1 (586bd68) | E13: Yes | F13: Changed on main: src/app/venues/[id]/edit/page.tsx, src/app/venues/page.tsx, src/lib/validation/venues.ts Shared files changed: prisma/schema.prisma, src/lib/permissions.ts | G13: =COUNTIF('Retested cases'!$B$5:$B$65,A13) -> 7
A14: SPM-40 | B14: Search and Filter Suitable Venues | C14: 2 | D14: Story merged 2026-09-28 (053464e) | E14: Yes | F14: Changed on main: src/app/api/events/[id]/route.ts, src/app/events/[id]/venue/page.tsx, src/lib/validation/venues.ts Changed by SPM-54 (not merged yet): src/app/venues/search/page.tsx, src/lib/venueSearchForm.ts Shared files changed: prisma/seed.ts, src/lib/permissions.ts | G14: =COUNTIF('Retested cases'!$B$5:$B$65,A14) -> 1
A15: SPM-41 | B15: Check Venue Suitability | C15: 2 | D15: Story merged 2026-09-27 (daf0788) | E15: Yes | F15: Changed on main: src/app/venues/page.tsx Shared files changed: prisma/schema.prisma, prisma/seed.ts | G15: =COUNTIF('Retested cases'!$B$5:$B$65,A15) -> 3
A16: SPM-42 | B16: Request Venue Booking | C16: 2 | D16: Story merged 2026-10-01 (3f0f2e1) | E16: Yes, once SPM-54 merges | F16: Changed by SPM-54 (not merged yet): src/lib/venueBookingRequest.ts Shared files changed: prisma/seed.ts, src/lib/permissions.ts | G16: =COUNTIF('Retested cases'!$B$5:$B$65,A16) -> 4
... A21: SPM-54 | B21: Begin Event Planning | C21: 2 | D21: In review, not merged yet | E21: No | F21: Finished this sprint; covered by its own test pass. | G21: =COUNTIF('Retested cases'!$B$5:$B$65,A21) -> 0
A23: Not listed: SPM-27, SPM-43, SPM-44 and SPM-50 are still in progress. If they merge before the sprint ends, they are tested by their own test cases this sprint, but check whether they change files that the stories above depend on.

Sheet Smoke run
A1: Sprint 2 regression: smoke run
A2: Take one new event, titled 'REG S2 <your name>', through the whole flow. Do not use any story's fixture events.
A4: Step | B4: Role | C4: What to do | D4: Result | E4: Tested by | F4: Notes
A5: 1 | B5: Event Organiser | C5: Log in, create an event request, save it as a draft, reopen it and submit it.
A6: 2 | B6: Event Operations Manager | C6: Assign an Event Coordinator to the submitted request.
A7: 3 | B7: Event Coordinator | C7: Review and approve the request.
A8: 4 | B8: Event Coordinator | C8: Begin planning, search for a venue, check its availability and submit a venue booking request.
A9: 5 | B9: Event Coordinator | C9: Record the equipment required.
A10: 6 | B10: Technical Support Staff | C10: Check equipment availability and reserve it.
A11: 7 | B11: Venue Staff | C11: Open the venue list, edit a venue and view its availability calendar.
A12: 8 | B12: Every role | C12: Each role sees only its own sidebar links, and the organiser sees only their own events.

Sheet Follow-ups
A1: Sprint 2 regression: follow-ups
A2: One row for each Fail (a bug) and each Changed by design or Blocked case (a test case to update).
A4: Type | B4: Test case ID | C4: Jira key | D4: Owner | E4: What needs doing | F4: Decision (fix now / next sprint) | G4: Done?
